<?xml version="1.0" encoding="UTF-8"?>
<robot xmlns:xacro="http://wiki.ros.org/xacro">

  <xacro:include filename="$(find denso_robot_description)/urdf/common.xacro" />

  <xacro:macro name="denso_robot" params="
    prefix 
    parent 
    *origin 
    initial_positions:=${dict(joint1=0.0,joint2=0.0,joint3=1.57,joint4=0.0,joint5=0.0,joint6=0.0)}"
    >
    <!-- LINKS -->
    <!-- base link -->
    <link name="${prefix}base_link">
      <!-- Default inertial for Gazebo/Ingnition - copy and edit block from 'common.xacro'
           to get more realistic behaviour-->
      <xacro:default_inertial/>
      <visual>
        <origin rpy="0 0 0" xyz="0 0 0" />
        <geometry>
          <mesh filename="package://denso_robot_description/meshes/denso_robot/visual/base_link.dae" />
        </geometry>
      </visual>
      <collision>
        <origin rpy="0 0 0" xyz="0 0 0" />
        <geometry>
          <mesh filename="package://denso_robot_description/meshes/denso_robot/visual/base_link.dae" />
        </geometry>
      </collision>
    </link>
    <!-- link 1 -->
    <link name="${prefix}link1">
      <!-- Default inertial for Gazebo/Ingnition - copy and edit block from 'common.xacro'
           to get more realistic behaviour-->
      <xacro:default_inertial/>
      <visual>
        <origin xyz="0 0 0" rpy="0 0 0" />
        <geometry>
          <mesh filename="package://denso_robot_description/meshes/denso_robot/visual/J1.dae" />
        </geometry>
      </visual>
      <collision>
        <origin xyz="0 0 0" rpy="0 0 0" />
        <geometry>
          <mesh filename="package://denso_robot_description/meshes/denso_robot/visual/J1.dae" />
        </geometry>
      </collision>
    </link>
    <!-- link 2 -->
    <link name="${prefix}link2">
      <!-- Default inertial for Gazebo/Ingnition - copy and edit block from 'common.xacro'
           to get more realistic behaviour-->
      <xacro:default_inertial/>
      <visual>
        <origin xyz="0 0 0" rpy="0 0 0" />
        <geometry>
          <mesh filename="package://denso_robot_description/meshes/denso_robot/visual/J2.dae" />
        </geometry>
      </visual>
      <collision>
        <origin xyz="0 0 0" rpy="0 0 0" />
        <geometry>
          <mesh filename="package://denso_robot_description/meshes/denso_robot/visual/J2.dae"  />
        </geometry>
      </collision>
    </link>
    <!-- link 3 -->
    <link name="${prefix}link3">
      <!-- Default inertial for Gazebo/Ingnition - copy and edit block from 'common.xacro'
           to get more realistic behaviour-->
      <xacro:default_inertial/>
      <visual>
        <origin xyz="0 0 0" rpy="0 0 0" />
        <geometry>
          <mesh filename="package://denso_robot_description/meshes/denso_robot/visual/J3.dae" />
        </geometry>
      </visual>
      <collision>
        <origin xyz="0 0 0" rpy="0 0 0" />
        <geometry>
          <mesh filename="package://denso_robot_description/meshes/denso_robot/visual/J3.dae"  />
        </geometry>
      </collision>
    </link>
    <!-- link 4 -->
    <link name="${prefix}link4">
      <!-- Default inertial for Gazebo/Ingnition - copy and edit block from 'common.xacro'
           to get more realistic behaviour-->
      <xacro:default_inertial/>
      <visual>
        <origin xyz="0 0 0" rpy="0 0 0" />
        <geometry>
          <mesh filename="package://denso_robot_description/meshes/denso_robot/visual/J4.dae" />
        </geometry>
      </visual>
      <collision>
        <origin xyz="0 0 0" rpy="0 0 0" />
        <geometry>
          <mesh filename="package://denso_robot_description/meshes/denso_robot/visual/J4.dae"  />
        </geometry>
      </collision>
    </link>
    <!-- link 5 -->
    <link name="${prefix}link5">
      <!-- Default inertial for Gazebo/Ingnition - copy and edit block from 'common.xacro'
           to get more realistic behaviour-->
      <xacro:default_inertial/>
      <visual>
        <origin xyz="0 0 0" rpy="0 0 0" />
        <geometry>
          <mesh filename="package://denso_robot_description/meshes/denso_robot/visual/J5.dae" />
        </geometry>
      </visual>
      <collision>
        <origin xyz="0 0 0" rpy="0 0 0" />
        <geometry>
          <mesh filename="package://denso_robot_description/meshes/denso_robot/visual/J5.dae" />
        </geometry>
      </collision>
    </link>
    <!-- link 6 -->
    <link name="${prefix}link6">
      <!-- Default inertial for Gazebo/Ingnition - copy and edit block from 'common.xacro'
           to get more realistic behaviour-->
      <xacro:default_inertial/>
      <visual>
        <origin xyz="0 0 0" rpy="0 0 0" />
        <geometry>
          <mesh filename="package://denso_robot_description/meshes/denso_robot/visual/J6.dae" />
        </geometry>
      </visual>
      <collision>
        <origin xyz="0 0 0" rpy="0 0 0" />
        <geometry>
          <mesh filename="package://denso_robot_description/meshes/denso_robot/visual/J6.dae" />
        </geometry>
      </collision>
    </link>

    <!-- All-zero tool frame. This frame should correspond to the TOOL frame of the robot's controller.) -->
    <link name="${prefix}tool0" />
    <!-- tool link -->

    <!-- END LINKS -->

    <!-- JOINTS -->
    <!-- base_joint fixes base_link to the environment -->
    <joint name="${prefix}base_joint" type="fixed">
      <xacro:insert_block name="origin" />
      <parent link="${parent}" />
      <child link="${prefix}base_link" />
    </joint>
    <!-- joint 1 -->
    <joint name="${prefix}joint1" type="revolute">
      <origin xyz="0 0 0.197500" rpy="0 0 0" />
      <parent link="${prefix}base_link" />
      <child link="${prefix}link1" />
      <axis xyz="0 0 1" />
      <limit effort="1000" lower="${radians(-170)}" upper="${radians(170)}" velocity="${radians(360)}" />
      <dynamics damping="0.7" friction="0.0"/>
    </joint>
    <!-- joint 2 -->
    <joint name="${prefix}joint2" type="revolute">
      <origin xyz="0.03 0 0.1975" rpy="0 0 0" />
      <parent link="${prefix}link1" />
      <child link="${prefix}link2" />
      <axis xyz="0 1 0" />
      <limit effort="1000" lower="${radians(-100)}" upper="${radians(135)}" velocity="${radians(300)}" />
      <dynamics damping="0.7" friction="0.0"/>
    </joint>
    <!-- joint 3 -->
    <joint name="${prefix}joint3" type="revolute">
      <origin xyz="0 0 0.445" rpy="0 0 0" />
      <parent link="${prefix}link2" />
      <child link="${prefix}link3" />
      <axis xyz="0 1 0" />
      <limit effort="1000" lower="${radians(-136)}" upper="${radians(153)}" velocity="${radians(408)}" />
      <dynamics damping="0.7" friction="0.0"/>
    </joint>
    <!-- joint 4 -->
    <joint name="${prefix}joint4" type="revolute">
      <origin xyz="-0.02 0 0.287" rpy="0 0 0" />
      <parent link="${prefix}link3" />
      <child link="${prefix}link4" />
      <axis xyz="0 0 1" />
      <limit effort="1000" lower="${radians(-270)}" upper="${radians(270)}" velocity="${radians(540)}" />
      <dynamics damping="0.7" friction="0.0"/>
    </joint>
    <!-- joint 5 -->
    <joint name="${prefix}joint5" type="revolute">
      <origin xyz="0 0 0.143" rpy="0 0 0" />
      <parent link="${prefix}link4" />
      <child link="${prefix}link5" />
      <axis xyz="0 1 0" />
      <limit effort="1000" lower="${radians(-120)}" upper="${radians(120)}" velocity="${radians(540)}" />
      <dynamics damping="0.7" friction="0.0"/>
    </joint>
    <!-- joint 6 -->
    <joint name="${prefix}joint6" type="revolute">
      <origin xyz="0 0 0.08" rpy="0 0 0" />
      <parent link="${prefix}link5" />
      <child link="${prefix}link6" />
      <axis xyz="0 0 1" />
      <limit effort="1000" lower="${radians(-360)}" upper="${radians(360)}" velocity="${radians(864)}" />
      <dynamics damping="0.7" friction="0.0"/>
    </joint>

    <!-- tool frame - fixed frame -->
    <joint name="${prefix}joint6-tool0" type="fixed">
      <parent link="${prefix}link6" />
      <child link="${prefix}tool0" />
      <origin xyz="0 0 -0.115" rpy="0 ${-pi} ${-pi/2}" />
    </joint>
    <!-- END JOINTS -->


  </xacro:macro>
</robot>
