<?xml version="1.0" encoding="utf-8"?>
<!-- =================================================================================== -->
<!-- |    This document was autogenerated by xacro from dual_manipulator_with_frame81.xacro | -->
<!-- |    EDITING THIS FILE BY HAND IS NOT RECOMMENDED                                 | -->
<!-- =================================================================================== -->
<robot name="dual_manipulator_with_frame">
  <gazebo>
    <plugin filename="libgazebo_ros_control.so" name="gazebo_ros_control">
      <robotNamespace>/dual_manipulator</robotNamespace>
    </plugin>
  </gazebo>
  <link name="base_link"/>
  <joint name="world_joint" type="fixed">
    <axis xyz="0 0 0"/>
    <origin rpy="0 0 0" xyz="0 0 0"/>
    <parent link="base_link"/>
    <child link="frame"/>
  </joint>
  <link name="frame">
    <visual>
      <origin rpy="0 0 0" xyz="0 0 0"/>
      <geometry>
        <mesh filename="package://denso_robot_descriptions/vs087_description/frame.dae"/>
      </geometry>
    </visual>
    <collision>
      <origin rpy="0 0 0" xyz="0 0 0"/>
      <geometry>
        <mesh filename="package://denso_robot_descriptions/vs087_description/frame.dae"/>
      </geometry>
    </collision>
    <inertial>
      <origin rpy="0 0 0" xyz="0 0 0"/>
      <mass value="100"/>
      <inertia ixx="1" ixy="0" ixz="0" iyy="1" iyz="0" izz="1"/>
    </inertial>
  </link>
  <joint name="joint_w_1" type="fixed">
    <origin rpy="3.14 0 -1.57" xyz="-0.5 -0.05 1.9"/>
    <parent link="frame"/>
    <child link="base_link_1"/>
  </joint>
  <link name="base_link_1">
    <visual>
      <origin rpy="0 0 0" xyz="0 0 0"/>
      <geometry>
        <mesh filename="package://denso_robot_descriptions/vs087_description/base_link.dae" scale="1 1 1"/>
      </geometry>
    </visual>
    <collision>
      <origin rpy="0 0 0" xyz="0 0 0"/>
      <geometry>
        <mesh filename="package://denso_robot_descriptions/vs087_description/base_link.dae" scale="1 1 1"/>
      </geometry>
    </collision>
    <inertial>
      <mass value="1"/>
      <origin rpy="0.000000 0.000000 0.000000" xyz="0.000000 0.000000 0.000000"/>
      <inertia ixx="1" ixy="0" ixz="0" iyy="1" iyz="0" izz="1"/>
    </inertial>
  </link>
  <link name="J1_1">
    <visual>
      <origin rpy="0 0 0" xyz="0 0 0"/>
      <geometry>
        <mesh filename="package://denso_robot_descriptions/vs087_description/J1.dae" scale="1 1 1"/>
      </geometry>
    </visual>
    <collision>
      <origin rpy="0 0 0" xyz="0 0 0"/>
      <geometry>
        <mesh filename="package://denso_robot_descriptions/vs087_description/J1.dae" scale="1 1 1"/>
      </geometry>
    </collision>
    <inertial>
      <mass value="1"/>
      <origin rpy="0.000000 0.000000 0.000000" xyz="0.000000 0.000000 0.000000"/>
      <inertia ixx="1" ixy="0" ixz="0" iyy="1" iyz="0" izz="1"/>
    </inertial>
  </link>
  <joint name="joint_1" type="revolute">
    <parent link="base_link_1"/>
    <child link="J1_1"/>
    <origin rpy="0.000000 0.000000 0.000000" xyz="0.000000 0.000000 0.197500"/>
    <axis xyz="-0.000000 -0.000000 1.000000"/>
    <limit effort="20" lower="-2.96705972839036" upper="2.96705972839036" velocity="5"/>
    <dynamics damping="0" friction="0"/>
  </joint>
  <transmission name="trans_1_1">
    <type>transmission_interface/SimpleTransmission</type>
    <joint name="joint_1">
      <hardwareInterface>hardware_interface/PositionJointInterface</hardwareInterface>
    </joint>
    <actuator name="motor_1_1">
      <hardwareInterface>hardware_interface/PositionJointInterface</hardwareInterface>
      <mechanicalReduction>1</mechanicalReduction>
    </actuator>
  </transmission>
  <link name="J2_1">
    <visual>
      <origin rpy="0 0 0" xyz="0 0 0"/>
      <geometry>
        <mesh filename="package://denso_robot_descriptions/vs087_description/J2.dae" scale="1 1 1"/>
      </geometry>
    </visual>
    <collision>
      <origin rpy="0 0 0" xyz="0 0 0"/>
      <geometry>
        <mesh filename="package://denso_robot_descriptions/vs087_description/J2.dae" scale="1 1 1"/>
      </geometry>
    </collision>
    <inertial>
      <mass value="1"/>
      <origin rpy="0.000000 0.000000 0.000000" xyz="0.000000 0.000000 0.000000"/>
      <inertia ixx="1" ixy="0" ixz="0" iyy="1" iyz="0" izz="1"/>
    </inertial>
  </link>
  <joint name="joint_2" type="revolute">
    <parent link="J1_1"/>
    <child link="J2_1"/>
    <origin rpy="0.000000 0.000000 0.000000" xyz="0.030000 0.000000 0.197500"/>
    <axis xyz="-0.000000 1.000000 -0.000000"/>
    <limit effort="30" lower="-1.74532925199433" upper="2.35619449019234" velocity="5"/>
    <dynamics damping="0" friction="0"/>
  </joint>
  <transmission name="trans_2_1">
    <type>transmission_interface/SimpleTransmission</type>
    <joint name="joint_2">
      <hardwareInterface>hardware_interface/PositionJointInterface</hardwareInterface>
    </joint>
    <actuator name="motor_2_1">
      <hardwareInterface>hardware_interface/PositionJointInterface</hardwareInterface>
      <mechanicalReduction>1</mechanicalReduction>
    </actuator>
  </transmission>
  <link name="J3_1">
    <visual>
      <origin rpy="0 0 0" xyz="0 0 0"/>
      <geometry>
        <mesh filename="package://denso_robot_descriptions/vs087_description/J3.dae" scale="1 1 1"/>
      </geometry>
    </visual>
    <collision>
      <origin rpy="0 0 0" xyz="0 0 0"/>
      <geometry>
        <mesh filename="package://denso_robot_descriptions/vs087_description/J3.dae" scale="1 1 1"/>
      </geometry>
    </collision>
    <inertial>
      <mass value="1"/>
      <origin rpy="0.000000 0.000000 0.000000" xyz="0.000000 0.000000 0.000000"/>
      <inertia ixx="1" ixy="0" ixz="0" iyy="1" iyz="0" izz="1"/>
    </inertial>
  </link>
  <joint name="joint_3" type="revolute">
    <parent link="J2_1"/>
    <child link="J3_1"/>
    <origin rpy="0.000000 0.000000 0.000000" xyz="0.000000 0.000000 0.445000"/>
    <axis xyz="-0.000000 1.000000 -0.000000"/>
    <limit effort="30" lower="-2.37364778271229" upper="2.67035375555132" velocity="5"/>
    <dynamics damping="0" friction="0"/>
  </joint>
  <transmission name="trans_3_1">
    <type>transmission_interface/SimpleTransmission</type>
    <joint name="joint_3">
      <hardwareInterface>hardware_interface/PositionJointInterface</hardwareInterface>
    </joint>
    <actuator name="motor_3_1">
      <hardwareInterface>hardware_interface/PositionJointInterface</hardwareInterface>
      <mechanicalReduction>1</mechanicalReduction>
    </actuator>
  </transmission>
  <link name="J4_1">
    <visual>
      <origin rpy="0 0 0" xyz="0 0 0"/>
      <geometry>
        <mesh filename="package://denso_robot_descriptions/vs087_description/J4.dae" scale="1 1 1"/>
      </geometry>
    </visual>
    <collision>
      <origin rpy="0 0 0" xyz="0 0 0"/>
      <geometry>
        <mesh filename="package://denso_robot_descriptions/vs087_description/J4.dae" scale="1 1 1"/>
      </geometry>
    </collision>
    <inertial>
      <mass value="1"/>
      <origin rpy="0.000000 0.000000 0.000000" xyz="0.000000 0.000000 0.000000"/>
      <inertia ixx="1" ixy="0" ixz="0" iyy="1" iyz="0" izz="1"/>
    </inertial>
  </link>
  <joint name="joint_4" type="revolute">
    <parent link="J3_1"/>
    <child link="J4_1"/>
    <origin rpy="0.000000 0.000000 0.000000" xyz="-0.020000 0.000000 0.287000"/>
    <axis xyz="-0.000000 -0.000000 1.000000"/>
    <limit effort="16.2" lower="-4.71238898038469" upper="4.71238898038469" velocity="5"/>
    <dynamics damping="0" friction="0"/>
  </joint>
  <transmission name="trans_4_1">
    <type>transmission_interface/SimpleTransmission</type>
    <joint name="joint_4">
      <hardwareInterface>hardware_interface/PositionJointInterface</hardwareInterface>
    </joint>
    <actuator name="motor_4_1">
      <hardwareInterface>hardware_interface/PositionJointInterface</hardwareInterface>
      <mechanicalReduction>1</mechanicalReduction>
    </actuator>
  </transmission>
  <link name="J5_1">
    <visual>
      <origin rpy="0 0 0" xyz="0 0 0"/>
      <geometry>
        <mesh filename="package://denso_robot_descriptions/vs087_description/J5.dae" scale="1 1 1"/>
      </geometry>
    </visual>
    <collision>
      <origin rpy="0 0 0" xyz="0 0 0"/>
      <geometry>
        <mesh filename="package://denso_robot_descriptions/vs087_description/J5.dae" scale="1 1 1"/>
      </geometry>
    </collision>
    <inertial>
      <mass value="1"/>
      <origin rpy="0.000000 0.000000 0.000000" xyz="0.000000 0.000000 0.000000"/>
      <inertia ixx="1" ixy="0" ixz="0" iyy="1" iyz="0" izz="1"/>
    </inertial>
  </link>
  <joint name="joint_5" type="revolute">
    <parent link="J4_1"/>
    <child link="J5_1"/>
    <origin rpy="0.000000 0.000000 0.000000" xyz="0.000000 0.000000 0.143000"/>
    <axis xyz="-0.000000 1.000000 -0.000000"/>
    <limit effort="16.2" lower="-2.0943951023932" upper="2.0943951023932" velocity="5"/>
    <dynamics damping="0" friction="0"/>
  </joint>
  <transmission name="trans_5_1">
    <type>transmission_interface/SimpleTransmission</type>
    <joint name="joint_5">
      <hardwareInterface>hardware_interface/PositionJointInterface</hardwareInterface>
    </joint>
    <actuator name="motor_5_1">
      <hardwareInterface>hardware_interface/PositionJointInterface</hardwareInterface>
      <mechanicalReduction>1</mechanicalReduction>
    </actuator>
  </transmission>
  <link name="J6_1">
    <visual>
      <origin rpy="0 0 0" xyz="0 0 0"/>
      <geometry>
        <mesh filename="package://denso_robot_descriptions/vs087_description/J6.dae" scale="1 1 1"/>
      </geometry>
    </visual>
    <collision>
      <origin rpy="0 0 0" xyz="0 0 0"/>
      <geometry>
        <mesh filename="package://denso_robot_descriptions/vs087_description/J6.dae" scale="1 1 1"/>
      </geometry>
    </collision>
    <inertial>
      <mass value="1"/>
      <origin rpy="0.000000 0.000000 0.000000" xyz="0.000000 0.000000 0.000000"/>
      <inertia ixx="1" ixy="0" ixz="0" iyy="1" iyz="0" izz="1"/>
    </inertial>
  </link>
  <joint name="joint_6" type="revolute">
    <parent link="J5_1"/>
    <child link="J6_1"/>
    <origin rpy="0.000000 0.000000 0.000000" xyz="0.000000 0.000000 0.080000"/>
    <axis xyz="-0.000000 -0.000000 1.000000"/>
    <limit effort="6.86" lower="-6.28318530717959" upper="6.28318530717959" velocity="5"/>
    <dynamics damping="0" friction="0"/>
  </joint>
  <transmission name="trans_6_1">
    <type>transmission_interface/SimpleTransmission</type>
    <joint name="joint_6">
      <hardwareInterface>hardware_interface/PositionJointInterface</hardwareInterface>
    </joint>
    <actuator name="motor_6_1">
      <hardwareInterface>hardware_interface/PositionJointInterface</hardwareInterface>
      <mechanicalReduction>1</mechanicalReduction>
    </actuator>
  </transmission>
  <link name="hand1">
    <visual>
      <origin rpy="0 0 0" xyz="0 0 0"/>
      <geometry>
        <mesh filename="package://denso_robot_descriptions/vs087_description/kondogripper.dae" scale="1 1 1"/>
      </geometry>
    </visual>
    <collision>
      <origin rpy="0 0 0" xyz="0 0 0"/>
      <geometry>
        <mesh filename="package://denso_robot_descriptions/vs087_description/kondogripper.dae" scale="1 1 1"/>
      </geometry>
    </collision>
    <inertial>
      <mass value="1"/>
      <origin rpy="0.000000 0.000000 0.000000" xyz="0.000000 0.000000 0.000000"/>
      <inertia ixx="1" ixy="0" ixz="0" iyy="1" iyz="0" izz="1"/>
    </inertial>
  </link>
  <joint name="handjoint_1" type="fixed">
    <parent link="J6_1"/>
    <child link="hand1"/>
    <origin rpy="0.000000 0.000000 0.000000" xyz="0.000000 0.000000 0.000000"/>
    <axis xyz="-0.000000 -0.000000 1.000000"/>
    <limit effort="10.0" lower="0.0" upper="0.0" velocity="1"/>
    <dynamics damping="0" friction="0"/>
  </joint>

  <link name="handtip1">
  </link>

  <joint name="handtip_1" type="fixed">
    <parent link="hand1"/>
    <child link="handtip1"/>
    <origin rpy="0.000000 0.0000 0.000000" xyz="0.000000 0.01200 0.12000"/>
    <axis xyz="-0.000000 -0.000000 0.000000"/>
    <limit effort="10.0" lower="0.0" upper="1.0471975512" velocity="1"/>
    <dynamics damping="0" friction="0"/>
  </joint>



  <joint name="joint_w_2" type="fixed">
    <origin rpy="3.14 0 -1.57" xyz="0.5 -0.05 1.9"/>
    <parent link="frame"/>
    <child link="base_link_2"/>
  </joint>

  <link name="base_link_2">
    <visual>
      <origin rpy="0 0 0" xyz="0 0 0"/>
      <geometry>
        <mesh filename="package://denso_robot_descriptions/vs087_description/base_link.dae" scale="1 1 1"/>
      </geometry>
    </visual>
    <collision>
      <origin rpy="0 0 0" xyz="0 0 0"/>
      <geometry>
        <mesh filename="package://denso_robot_descriptions/vs087_description/base_link.dae" scale="1 1 1"/>
      </geometry>
    </collision>
    <inertial>
      <mass value="1"/>
      <origin rpy="0.000000 0.000000 0.000000" xyz="0.000000 0.000000 0.000000"/>
      <inertia ixx="1" ixy="0" ixz="0" iyy="1" iyz="0" izz="1"/>
    </inertial>
  </link>
  <link name="J1_2">
    <visual>
      <origin rpy="0 0 0" xyz="0 0 0"/>
      <geometry>
        <mesh filename="package://denso_robot_descriptions/vs087_description/J1.dae" scale="1 1 1"/>
      </geometry>
    </visual>
    <collision>
      <origin rpy="0 0 0" xyz="0 0 0"/>
      <geometry>
        <mesh filename="package://denso_robot_descriptions/vs087_description/J1.dae" scale="1 1 1"/>
      </geometry>
    </collision>
    <inertial>
      <mass value="1"/>
      <origin rpy="0.000000 0.000000 0.000000" xyz="0.000000 0.000000 0.000000"/>
      <inertia ixx="1" ixy="0" ixz="0" iyy="1" iyz="0" izz="1"/>
    </inertial>
  </link>
  <joint name="joint_7" type="revolute">
    <parent link="base_link_2"/>
    <child link="J1_2"/>
    <origin rpy="0.000000 0.000000 0.000000" xyz="0.000000 0.000000 0.197500"/>
    <axis xyz="-0.000000 -0.000000 1.000000"/>
    <limit effort="10" lower="-2.96705972839036" upper="2.96705972839036" velocity="5"/>
    <dynamics damping="0" friction="0"/>
  </joint>
  <transmission name="trans_1_2">
    <type>transmission_interface/SimpleTransmission</type>
    <joint name="joint_7">
      <hardwareInterface>hardware_interface/PositionJointInterface</hardwareInterface>
    </joint>
    <actuator name="motor_1_2">
      <hardwareInterface>hardware_interface/PositionJointInterface</hardwareInterface>
      <mechanicalReduction>1</mechanicalReduction>
    </actuator>
  </transmission>
  <link name="J2_2">
    <visual>
      <origin rpy="0 0 0" xyz="0 0 0"/>
      <geometry>
        <mesh filename="package://denso_robot_descriptions/vs087_description/J2.dae" scale="1 1 1"/>
      </geometry>
    </visual>
    <collision>
      <origin rpy="0 0 0" xyz="0 0 0"/>
      <geometry>
        <mesh filename="package://denso_robot_descriptions/vs087_description/J2.dae" scale="1 1 1"/>
      </geometry>
    </collision>
    <inertial>
      <mass value="1"/>
      <origin rpy="0.000000 0.000000 0.000000" xyz="0.000000 0.000000 0.000000"/>
      <inertia ixx="1" ixy="0" ixz="0" iyy="1" iyz="0" izz="1"/>
    </inertial>
  </link>
  <joint name="joint_8" type="revolute">
    <parent link="J1_2"/>
    <child link="J2_2"/>
    <origin rpy="0.000000 0.000000 0.000000" xyz="0.030000 0.000000 0.197500"/>
    <axis xyz="-0.000000 1.000000 -0.000000"/>
    <limit effort="50" lower="-1.74532925199433" upper="2.35619449019234" velocity="5"/>
    <dynamics damping="0" friction="0"/>
  </joint>
  <transmission name="trans_2_2">
    <type>transmission_interface/SimpleTransmission</type>
    <joint name="joint_8">
      <hardwareInterface>hardware_interface/PositionJointInterface</hardwareInterface>
    </joint>
    <actuator name="motor_2_2">
      <hardwareInterface>hardware_interface/PositionJointInterface</hardwareInterface>
      <mechanicalReduction>1</mechanicalReduction>
    </actuator>
  </transmission>
  <link name="J3_2">
    <visual>
      <origin rpy="0 0 0" xyz="0 0 0"/>
      <geometry>
        <mesh filename="package://denso_robot_descriptions/vs087_description/J3.dae" scale="1 1 1"/>
      </geometry>
    </visual>
    <collision>
      <origin rpy="0 0 0" xyz="0 0 0"/>
      <geometry>
        <mesh filename="package://denso_robot_descriptions/vs087_description/J3.dae" scale="1 1 1"/>
      </geometry>
    </collision>
    <inertial>
      <mass value="1"/>
      <origin rpy="0.000000 0.000000 0.000000" xyz="0.000000 0.000000 0.000000"/>
      <inertia ixx="1" ixy="0" ixz="0" iyy="1" iyz="0" izz="1"/>
    </inertial>
  </link>
  <joint name="joint_9" type="revolute">
    <parent link="J2_2"/>
    <child link="J3_2"/>
    <origin rpy="0.000000 0.000000 0.000000" xyz="0.000000 0.000000 0.445000"/>
    <axis xyz="-0.000000 1.000000 -0.000000"/>
    <limit effort="50" lower="-2.37364778271229" upper="2.67035375555132" velocity="5"/>
    <dynamics damping="0" friction="0"/>
  </joint>
  <transmission name="trans_3_2">
    <type>transmission_interface/SimpleTransmission</type>
    <joint name="joint_9">
      <hardwareInterface>hardware_interface/PositionJointInterface</hardwareInterface>
    </joint>
    <actuator name="motor_3_2">
      <hardwareInterface>hardware_interface/PositionJointInterface</hardwareInterface>
      <mechanicalReduction>1</mechanicalReduction>
    </actuator>
  </transmission>
  <link name="J4_2">
    <visual>
      <origin rpy="0 0 0" xyz="0 0 0"/>
      <geometry>
        <mesh filename="package://denso_robot_descriptions/vs087_description/J4.dae" scale="1 1 1"/>
      </geometry>
    </visual>
    <collision>
      <origin rpy="0 0 0" xyz="0 0 0"/>
      <geometry>
        <mesh filename="package://denso_robot_descriptions/vs087_description/J4.dae" scale="1 1 1"/>
      </geometry>
    </collision>
    <inertial>
      <mass value="1"/>
      <origin rpy="0.000000 0.000000 0.000000" xyz="0.000000 0.000000 0.000000"/>
      <inertia ixx="1" ixy="0" ixz="0" iyy="1" iyz="0" izz="1"/>
    </inertial>
  </link>
  <joint name="joint_10" type="revolute">
    <parent link="J3_2"/>
    <child link="J4_2"/>
    <origin rpy="0.000000 0.000000 0.000000" xyz="-0.020000 0.000000 0.287000"/>
    <axis xyz="-0.000000 -0.000000 1.000000"/>
    <limit effort="16.2" lower="-4.71238898038469" upper="4.71238898038469" velocity="5"/>
    <dynamics damping="0" friction="0"/>
  </joint>
  <transmission name="trans_4_2">
    <type>transmission_interface/SimpleTransmission</type>
    <joint name="joint_10">
      <hardwareInterface>hardware_interface/PositionJointInterface</hardwareInterface>
    </joint>
    <actuator name="motor_4_2">
      <hardwareInterface>hardware_interface/PositionJointInterface</hardwareInterface>
      <mechanicalReduction>1</mechanicalReduction>
    </actuator>
  </transmission>
  <link name="J5_2">
    <visual>
      <origin rpy="0 0 0" xyz="0 0 0"/>
      <geometry>
        <mesh filename="package://denso_robot_descriptions/vs087_description/J5.dae" scale="1 1 1"/>
      </geometry>
    </visual>
    <collision>
      <origin rpy="0 0 0" xyz="0 0 0"/>
      <geometry>
        <mesh filename="package://denso_robot_descriptions/vs087_description/J5.dae" scale="1 1 1"/>
      </geometry>
    </collision>
    <inertial>
      <mass value="1"/>
      <origin rpy="0.000000 0.000000 0.000000" xyz="0.000000 0.000000 0.000000"/>
      <inertia ixx="1" ixy="0" ixz="0" iyy="1" iyz="0" izz="1"/>
    </inertial>
  </link>
  <joint name="joint_11" type="revolute">
    <parent link="J4_2"/>
    <child link="J5_2"/>
    <origin rpy="0.000000 0.000000 0.000000" xyz="0.000000 0.000000 0.143000"/>
    <axis xyz="-0.000000 1.000000 -0.000000"/>
    <limit effort="16.2" lower="-2.0943951023932" upper="2.0943951023932" velocity="5"/>
    <dynamics damping="0" friction="0"/>
  </joint>
  <transmission name="trans_5_2">
    <type>transmission_interface/SimpleTransmission</type>
    <joint name="joint_11">
      <hardwareInterface>hardware_interface/PositionJointInterface</hardwareInterface>
    </joint>
    <actuator name="motor_5_2">
      <hardwareInterface>hardware_interface/PositionJointInterface</hardwareInterface>
      <mechanicalReduction>1</mechanicalReduction>
    </actuator>
  </transmission>
  <link name="J6_2">
    <visual>
      <origin rpy="0 0 0" xyz="0 0 0"/>
      <geometry>
        <mesh filename="package://denso_robot_descriptions/vs087_description/J6.dae" scale="1 1 1"/>
      </geometry>
    </visual>
    <collision>
      <origin rpy="0 0 0" xyz="0 0 0"/>
      <geometry>
        <mesh filename="package://denso_robot_descriptions/vs087_description/J6.dae" scale="1 1 1"/>
      </geometry>
    </collision>
    <inertial>
      <mass value="1"/>
      <origin rpy="0.000000 0.000000 0.000000" xyz="0.000000 0.000000 0.000000"/>
      <inertia ixx="1" ixy="0" ixz="0" iyy="1" iyz="0" izz="1"/>
    </inertial>
  </link>
  <joint name="joint_12" type="revolute">
    <parent link="J5_2"/>
    <child link="J6_2"/>
    <origin rpy="0.000000 0.000000 0.000000" xyz="0.000000 0.000000 0.080000"/>
    <axis xyz="-0.000000 -0.000000 1.000000"/>
    <limit effort="6.86" lower="-6.28318530717959" upper="6.28318530717959" velocity="5"/>
    <dynamics damping="0" friction="0"/>
  </joint>
  <transmission name="trans_6_2">
    <type>transmission_interface/SimpleTransmission</type>
    <joint name="joint_12">
      <hardwareInterface>hardware_interface/PositionJointInterface</hardwareInterface>
    </joint>
    <actuator name="motor_6_2">
      <hardwareInterface>hardware_interface/PositionJointInterface</hardwareInterface>
      <mechanicalReduction>1</mechanicalReduction>
    </actuator>
  </transmission>
  <link name="hand2">
    <visual>
      <origin rpy="0 0 0" xyz="0 0 0"/>
      <geometry>
        <mesh filename="package://denso_robot_descriptions/vs087_description/kondogripper.dae" scale="1 1 1"/>
      </geometry>
    </visual>
    <collision>
      <origin rpy="0 0 0" xyz="0 0 0"/>
      <geometry>
        <mesh filename="package://denso_robot_descriptions/vs087_description/kondogripper.dae" scale="1 1 1"/>
      </geometry>
    </collision>
    <inertial>
      <mass value="1"/>
      <origin rpy="0.000000 0.000000 0.000000" xyz="0.000000 0.000000 0.000000"/>
      <inertia ixx="1" ixy="0" ixz="0" iyy="1" iyz="0" izz="1"/>
    </inertial>
  </link>
  <joint name="handjoint_2" type="fixed">
    <parent link="J6_2"/>
    <child link="hand2"/>
    <origin rpy="0.000000 0.000000 0.000000" xyz="0.000000 0.000000 0.000000"/>
    <axis xyz="-0.000000 -0.000000 1.000000"/>
    <limit effort="10.0" lower="0.0" upper="1.0471975512" velocity="1"/>
    <dynamics damping="0" friction="0"/>
  </joint>

   <link name="handtip2">
  </link>

  <joint name="handtip_2" type="fixed">
    <parent link="hand2"/>
    <child link="handtip2"/>
    <origin rpy="0.000000 0.0000 0.000000" xyz="0.000000 0.01200 0.12000"/>
    <axis xyz="-0.000000 -0.000000 0.000000"/>
    <limit effort="10.0" lower="0.0" upper="1.0471975512" velocity="1"/>
    <dynamics damping="0" friction="0"/>
  </joint>

  <gazebo reference="frame">
    <selfCollide>false</selfCollide>
  </gazebo>
</robot>

