<robot name="vs087_description">
	<gazebo>
		<plugin name="gazebo_ros_control" filename="libgazebo_ros_control.so">
			<robotNamespace>/vs087</robotNamespace>
		</plugin>
	</gazebo>
	<link name="world"/>
	<joint name="joint_w" type="fixed">
		<parent link="world"/>
		<child link="base_link"/>
	</joint>
	<link name="base_link">
		<visual>
			<origin rpy="0 0 0" xyz="0 0 0"/>
			<geometry>
				<mesh filename="package://denso_robot_descriptions/vs087_description/base_link.dae" scale="1 1 1"/>
			</geometry>
		</visual>
		<collision>
			<origin rpy="0 0 0" xyz="0 0 0"/>
			<geometry>
				<mesh filename="package://denso_robot_descriptions/vs087_description/base_link.dae" scale="1 1 1"/>
			</geometry>
		</collision>
		<inertial>
			<mass value="1"/>
			<origin rpy="0.000000 0.000000 0.000000" xyz="0.000000 0.000000 0.000000"/>
			<inertia ixx="1" ixy="0" ixz="0" iyy="1" iyz="0" izz="1"/>
		</inertial>
	</link>
	<link name="J1">
		<visual>
			<origin rpy="0 0 0" xyz="0 0 0"/>
			<geometry>
				<mesh filename="package://denso_robot_descriptions/vs087_description/J1.dae" scale="1 1 1" />
			</geometry>
		</visual>
		<collision>
			<origin rpy="0 0 0" xyz="0 0 0"/>
			<geometry>
				<mesh filename="package://denso_robot_descriptions/vs087_description/J1.dae" scale="1 1 1"/>
			</geometry>
		</collision>
		<inertial>
			<mass value="1"/>
			<origin rpy="0.000000 0.000000 0.000000" xyz="0.000000 0.000000 0.000000"/>
			<inertia ixx="1" ixy="0" ixz="0" iyy="1" iyz="0" izz="1"/>
		</inertial>
	</link>
	<joint name="joint_1" type="revolute">
		<parent link="base_link"/>
		<child link="J1"/>
		<origin rpy="0.000000 0.000000 0.000000" xyz="0.000000 0.000000 0.197500"/>
		<axis xyz="-0.000000 -0.000000 1.000000"/>
		<limit effort="1" lower="-2.96705972839036" upper="2.96705972839036" velocity="3.92699081698724"/>
		<dynamics damping="0" friction="0"/>
	</joint>
	<transmission name="trans_1">
		<type>transmission_interface/SimpleTransmission</type>
		<joint name="joint_1">
			<hardwareInterface>hardware_interface/PositionJointInterface</hardwareInterface>
		</joint>
		<actuator name="motor_1">
			<hardwareInterface>hardware_interface/PositionJointInterface</hardwareInterface>
			<mechanicalReduction>1</mechanicalReduction>
		</actuator>
	</transmission>
	<link name="J2">
		<visual>
			<origin rpy="0 0 0" xyz="0 0 0"/>
			<geometry>
				<mesh filename="package://denso_robot_descriptions/vs087_description/J2.dae" scale="1 1 1"/>
			</geometry>
		</visual>
		<collision>
			<origin rpy="0 0 0" xyz="0 0 0"/>
			<geometry>
				<mesh filename="package://denso_robot_descriptions/vs087_description/J2.dae" scale="1 1 1"/>
			</geometry>
		</collision>
		<inertial>
			<mass value="1"/>
			<origin rpy="0.000000 0.000000 0.000000" xyz="0.000000 0.000000 0.000000"/>
			<inertia ixx="1" ixy="0" ixz="0" iyy="1" iyz="0" izz="1"/>
		</inertial>
	</link>
	<joint name="joint_2" type="revolute">
		<parent link="J1"/>
		<child link="J2"/>
		<origin rpy="0.000000 0.000000 0.000000" xyz="0.030000 0.000000 0.197500"/>
		<axis xyz="-0.000000 1.000000 -0.000000"/>
		<limit effort="1" lower="-1.74532925199433" upper="2.35619449019234" velocity="2.61799387799149"/>
		<dynamics damping="0" friction="0"/>
	</joint>
	<transmission name="trans_2">
		<type>transmission_interface/SimpleTransmission</type>
		<joint name="joint_2">
			<hardwareInterface>hardware_interface/PositionJointInterface</hardwareInterface>
		</joint>
		<actuator name="motor_2">
			<hardwareInterface>hardware_interface/PositionJointInterface</hardwareInterface>
			<mechanicalReduction>1</mechanicalReduction>
		</actuator>
	</transmission>
	<link name="J3">
		<visual>
			<origin rpy="0 0 0" xyz="0 0 0"/>
			<geometry>
				<mesh filename="package://denso_robot_descriptions/vs087_description/J3.dae" scale="1 1 1"/>
			</geometry>
		</visual>
		<collision>
			<origin rpy="0 0 0" xyz="0 0 0"/>
			<geometry>
				<mesh filename="package://denso_robot_descriptions/vs087_description/J3.dae" scale="1 1 1"/>
			</geometry>
		</collision>
		<inertial>
			<mass value="1"/>
			<origin rpy="0.000000 0.000000 0.000000" xyz="0.000000 0.000000 0.000000"/>
			<inertia ixx="1" ixy="0" ixz="0" iyy="1" iyz="0" izz="1"/>
		</inertial>
	</link>
	<joint name="joint_3" type="revolute">
		<parent link="J2"/>
		<child link="J3"/>
		<origin rpy="0.000000 0.000000 0.000000" xyz="0.000000 0.000000 0.445000"/>
		<axis xyz="-0.000000 1.000000 -0.000000"/>
		<limit effort="1" lower="-2.37364778271229" upper="2.67035375555132" velocity="2.85832571599111"/>
		<dynamics damping="0" friction="0"/>
	</joint>
	<transmission name="trans_3">
		<type>transmission_interface/SimpleTransmission</type>
		<joint name="joint_3">
			<hardwareInterface>hardware_interface/PositionJointInterface</hardwareInterface>
		</joint>
		<actuator name="motor_3">
			<hardwareInterface>hardware_interface/PositionJointInterface</hardwareInterface>
			<mechanicalReduction>1</mechanicalReduction>
		</actuator>
	</transmission>
	<link name="J4">
		<visual>
			<origin rpy="0 0 0" xyz="0 0 0"/>
			<geometry>
				<mesh filename="package://denso_robot_descriptions/vs087_description/J4.dae" scale="1 1 1"/>
			</geometry>
		</visual>
		<collision>
			<origin rpy="0 0 0" xyz="0 0 0"/>
			<geometry>
				<mesh filename="package://denso_robot_descriptions/vs087_description/J4.dae" scale="1 1 1"/>
			</geometry>
		</collision>
		<inertial>
			<mass value="1"/>
			<origin rpy="0.000000 0.000000 0.000000" xyz="0.000000 0.000000 0.000000"/>
			<inertia ixx="1" ixy="0" ixz="0" iyy="1" iyz="0" izz="1"/>
		</inertial>
	</link>
	<joint name="joint_4" type="revolute">
		<parent link="J3"/>
		<child link="J4"/>
		<origin rpy="0.000000 0.000000 0.000000" xyz="-0.020000 0.000000 0.287000"/>
		<axis xyz="-0.000000 -0.000000 1.000000"/>
		<limit effort="1" lower="-4.71238898038469" upper="4.71238898038469" velocity="3.92699081698724"/>
		<dynamics damping="0" friction="0"/>
	</joint>
	<transmission name="trans_4">
		<type>transmission_interface/SimpleTransmission</type>
		<joint name="joint_4">
			<hardwareInterface>hardware_interface/PositionJointInterface</hardwareInterface>
		</joint>
		<actuator name="motor_4">
			<hardwareInterface>hardware_interface/PositionJointInterface</hardwareInterface>
			<mechanicalReduction>1</mechanicalReduction>
		</actuator>
	</transmission>
	<link name="J5">
		<visual>
			<origin rpy="0 0 0" xyz="0 0 0"/>
			<geometry>
				<mesh filename="package://denso_robot_descriptions/vs087_description/J5.dae" scale="1 1 1"/>
			</geometry>
		</visual>
		<collision>
			<origin rpy="0 0 0" xyz="0 0 0"/>
			<geometry>
				<mesh filename="package://denso_robot_descriptions/vs087_description/J5.dae" scale="1 1 1"/>
			</geometry>
		</collision>
		<inertial>
			<mass value="1"/>
			<origin rpy="0.000000 0.000000 0.000000" xyz="0.000000 0.000000 0.000000"/>
			<inertia ixx="1" ixy="0" ixz="0" iyy="1" iyz="0" izz="1"/>
		</inertial>
	</link>
	<joint name="joint_5" type="revolute">
		<parent link="J4"/>
		<child link="J5"/>
		<origin rpy="0.000000 0.000000 0.000000" xyz="0.000000 0.000000 0.143000"/>
		<axis xyz="-0.000000 1.000000 -0.000000"/>
		<limit effort="1" lower="-2.0943951023932" upper="2.0943951023932" velocity="3.02168853397778"/>
		<dynamics damping="0" friction="0"/>
	</joint>
	<transmission name="trans_5">
		<type>transmission_interface/SimpleTransmission</type>
		<joint name="joint_5">
			<hardwareInterface>hardware_interface/PositionJointInterface</hardwareInterface>
		</joint>
		<actuator name="motor_5">
			<hardwareInterface>hardware_interface/PositionJointInterface</hardwareInterface>
			<mechanicalReduction>1</mechanicalReduction>
		</actuator>
	</transmission>
	<link name="J6">
		<visual>
			<origin rpy="0 0 0" xyz="0 0 0"/>
			<geometry>
				<mesh filename="package://denso_robot_descriptions/vs087_description/J6.dae" scale="1 1 1"/>
			</geometry>
		</visual>
		<collision>
			<origin rpy="0 0 0" xyz="0 0 0"/>
			<geometry>
				<mesh filename="package://denso_robot_descriptions/vs087_description/J6.dae" scale="1 1 1"/>
			</geometry>
		</collision>
		<inertial>
			<mass value="1"/>
			<origin rpy="0.000000 0.000000 0.000000" xyz="0.000000 0.000000 0.000000"/>
			<inertia ixx="1" ixy="0" ixz="0" iyy="1" iyz="0" izz="1"/>
		</inertial>
	</link>
	<joint name="joint_6" type="revolute">
		<parent link="J5"/>
		<child link="J6"/>
		<origin rpy="0.000000 0.000000 0.000000" xyz="0.000000 0.000000 0.080000"/>
		<axis xyz="-0.000000 -0.000000 1.000000"/>
		<limit effort="1" lower="-6.28318530717959" upper="6.28318530717959" velocity="6.28318530717959"/>
		<dynamics damping="0" friction="0"/>
	</joint>
	<transmission name="trans_6">
		<type>transmission_interface/SimpleTransmission</type>
		<joint name="joint_6">
			<hardwareInterface>hardware_interface/PositionJointInterface</hardwareInterface>
		</joint>
		<actuator name="motor_6">
			<hardwareInterface>hardware_interface/PositionJointInterface</hardwareInterface>
			<mechanicalReduction>1</mechanicalReduction>
		</actuator>
	</transmission>
</robot>
