<?xml version="1.0"?>
<!-- Copyright (C) 2019, TechMagic K.K. -->
<robot xmlns:xacro="http://www.ros.org/wiki/xacro">
  <xacro:property name="folder" value="package://denso_robot_descriptions/vs068_description/mesh"/>
  <xacro:macro name="vs068" params="parent *origin">
    <gazebo>
      <plugin filename="libgazebo_ros_control.so" name="gazebo_ros_control">
	<robotNamespace>/vs068</robotNamespace>
      </plugin>
    </gazebo>
    <joint name="base_joint" type="fixed">
      <xacro:insert_block name="origin"/>
      <parent link="${parent}"/>
      <child link="J0"/>
    </joint>    
    <link name="J0">
      <visual>
	<origin rpy="0 0 0" xyz="0 0 0"/>
	<geometry>
	  <mesh filename="${folder}/base_link.stl"/>
	</geometry>
	<material name="white"/>
      </visual>
      <collision>
	<origin rpy="0 0 0" xyz="0 0 0" />
	<geometry>
	  <mesh filename="${folder}/base_link.stl"/>
	</geometry>
      </collision>
      <inertial>
	<mass value="1" />
	<origin rpy="0.000000 0.000000 0.000000" xyz="0.000000 0.000000 0.000000" />
	<inertia ixx="1" ixy="0" ixz="0" iyy="1" iyz="0" izz="1" />
      </inertial>
    </link>
    <link name="J1">
      <visual>
	<origin rpy="0 0 0" xyz="0 0 0" />
	<geometry>
	  <mesh filename="${folder}/J1.stl" scale="1 1 1" />
	</geometry>
	<material name="white"/>
      </visual>
      <collision>
	<origin rpy="0 0 0" xyz="0 0 0" />
	<geometry>
	  <mesh filename="${folder}/J1.stl" scale="1 1 1" />
	</geometry>
      </collision>
      <inertial>
	<mass value="1" />
	<origin rpy="0.000000 0.000000 0.000000" xyz="0.000000 0.000000 0.000000" />
	<inertia ixx="1" ixy="0" ixz="0" iyy="1" iyz="0" izz="1" />
      </inertial>
    </link>
    <joint name="joint_1" type="revolute">
      <parent link="J0" />
      <child link="J1" />
      <origin rpy="0.000000 0.000000 0.000000" xyz="0.000000 0.000000 0.1975" />
      <axis xyz="0.000000 0.000000 1.000000" />
      <limit effort="1" lower="-2.8797932657906435" upper="2.8797932657906435" velocity="3.92699081698724" />
      <dynamics damping="0" friction="0" />
    </joint>
    <transmission name="trans_1">
      <type>transmission_interface/SimpleTransmission</type>
      <joint name="joint_1">
	<hardwareInterface>PositionJointInterface</hardwareInterface>
      </joint>
      <actuator name="motor_1">
	<hardwareInterface>PositionJointInterface</hardwareInterface>
	<mechanicalReduction>1</mechanicalReduction>
      </actuator>
    </transmission>
    <link name="J2">
      <visual>
	<origin rpy="0 0 0" xyz="0 0 0" />
	<geometry>
	  <mesh filename="${folder}/J2.stl" scale="1 1 1" />
	</geometry>
	<material name="white"/>
      </visual>
      <collision>
	<origin rpy="0 0 0" xyz="0 0 0" />
	<geometry>
	  <mesh filename="${folder}/J2.stl" scale="1 1 1" />
	</geometry>
      </collision>
      <inertial>
	<mass value="1" />
	<origin rpy="0.000000 0.000000 0.000000" xyz="0.000000 0.000000 0.000000" />
	<inertia ixx="1" ixy="0" ixz="0" iyy="1" iyz="0" izz="1" />
      </inertial>
    </link>
    <joint name="joint_2" type="revolute">
      <parent link="J1" />
      <child link="J2" />
      <origin rpy="0.000000 0.000000 0.000000" xyz="0.030 0.000 0.1975" />
      <axis xyz="0.000000 1.000000 0.000000" />
      <limit effort="1" lower="-0.3" upper="2.2689280275926285" velocity="2.61799387799149" />
      <dynamics damping="0" friction="0" />
    </joint>
    <transmission name="trans_2">
      <type>transmission_interface/SimpleTransmission</type>
      <joint name="joint_2">
	<hardwareInterface>PositionJointInterface</hardwareInterface>
      </joint>
      <actuator name="motor_2">
	<hardwareInterface>PositionJointInterface</hardwareInterface>
	<mechanicalReduction>1</mechanicalReduction>
      </actuator>
    </transmission>
    <link name="J3">
      <visual>
	<origin rpy="0 0 0" xyz="0 0 0" />
	<geometry>
	  <mesh filename="${folder}/J3.stl" scale="1 1 1" />
	</geometry>
	<material name="white"/>
      </visual>
      <collision>
	<origin rpy="0 0 0" xyz="0 0 0" />
	<geometry>
	  <mesh filename="${folder}/J3.stl" scale="1 1 1" />
	</geometry>
      </collision>
      <inertial>
	<mass value="1" />
	<origin rpy="0.000000 0.000000 0.000000" xyz="0.000000 0.000000 0.000000" />
	<inertia ixx="1" ixy="0" ixz="0" iyy="1" iyz="0" izz="1" />
      </inertial>
    </link>
    <joint name="joint_3" type="revolute">
      <parent link="J2" />
      <child link="J3" />
      <origin rpy="0.000000 0.000000 0.000000" xyz="0.000000 0.000000 0.340" />
      <axis xyz="0.000000 1.000000 0.000000" />
      <limit effort="1" lower="0.9594" upper="2.356194490192345" velocity="2.85832571599111" />
      <dynamics damping="0" friction="0" />
    </joint>
    <transmission name="trans_3">
      <type>transmission_interface/SimpleTransmission</type>
      <joint name="joint_3">
	<hardwareInterface>PositionJointInterface</hardwareInterface>
      </joint>
      <actuator name="motor_3">
	<hardwareInterface>PositionJointInterface</hardwareInterface>
	<mechanicalReduction>1</mechanicalReduction>
      </actuator>
    </transmission>
    <link name="J4">
      <visual>
	<origin rpy="0 0 0" xyz="0 0 0" />
	<geometry>
	  <mesh filename="${folder}/J4.stl" scale="1 1 1" />
	</geometry>
	<material name="white"/>
      </visual>
      <collision>
	<origin rpy="0 0 0" xyz="0 0 0" />
	<geometry>
	  <mesh filename="${folder}/J4.stl" scale="1 1 1" />
	</geometry>
      </collision>
      <inertial>
	<mass value="1" />
	<origin rpy="0.000000 0.000000 0.000000" xyz="0.000000 0.000000 0.000000" />
	<inertia ixx="1" ixy="0" ixz="0" iyy="1" iyz="0" izz="1" />
      </inertial>
    </link>
    <joint name="joint_4" type="revolute">
      <parent link="J3" />
      <child link="J4" />
      <origin rpy="0.000000 0.000000 0.000000" xyz="-0.020 0.000 0.197" />
      <axis xyz="0.000000 0.000000 1.000000" />
      <limit effort="1" lower="-2.705260340591211" upper="2.705260340591211" velocity="3.92699081698724" />
      <dynamics damping="0" friction="0" />
    </joint>
    <transmission name="trans_4">
      <type>transmission_interface/SimpleTransmission</type>
      <joint name="joint_4">
	<hardwareInterface>PositionJointInterface</hardwareInterface>
      </joint>
      <actuator name="motor_4">
	<hardwareInterface>PositionJointInterface</hardwareInterface>
	<mechanicalReduction>1</mechanicalReduction>
      </actuator>
    </transmission>
    <link name="J5">
      <visual>
	<origin rpy="0 0 0" xyz="0 0 0" />
	<geometry>
	  <mesh filename="${folder}/J5.stl" scale="1 1 1" />
	</geometry>
	<material name="grey"/>
      </visual>
      <collision>
	<origin rpy="0 0 0" xyz="0 0 0" />
	<geometry>
	  <mesh filename="${folder}/J5.stl" scale="1 1 1" />
	</geometry>
      </collision>
      <inertial>
	<mass value="1" />
	<origin rpy="0.000000 0.000000 0.000000" xyz="0.000000 0.000000 0.000000" />
	<inertia ixx="1" ixy="0" ixz="0" iyy="1" iyz="0" izz="1" />
      </inertial>
    </link>
    <joint name="joint_5" type="revolute">
      <parent link="J4" />
      <child link="J5" />
      <origin rpy="0.000000 0.000000 0.000000" xyz="0.000000 0.000000 0.143" />
      <axis xyz="-0.000000 1.000000 -0.000000" />
      <limit effort="1" lower="-2.007128639793479" upper="2.007128639793479" velocity="3.02168853397778" />
      <dynamics damping="0" friction="0" />
    </joint>
    <transmission name="trans_5">
      <type>transmission_interface/SimpleTransmission</type>
      <joint name="joint_5">
	<hardwareInterface>PositionJointInterface</hardwareInterface>
      </joint>
      <actuator name="motor_5">
	<hardwareInterface>PositionJointInterface</hardwareInterface>
	<mechanicalReduction>1</mechanicalReduction>
      </actuator>
    </transmission>
    <link name="J6">
      <inertial>
	<mass value="1" />
	<origin rpy="0.000000 0.000000 0.000000" xyz="0.000000 0.000000 0.000000" />
	<inertia ixx="1" ixy="0" ixz="0" iyy="1" iyz="0" izz="1" />
      </inertial>
    </link>
    <joint name="joint_6" type="revolute">
      <parent link="J5" />
      <child link="J6" />
      <origin rpy="0.000000 0.000000 0.000000" xyz="0.000000 0.000000 0.115" />
      <axis xyz="-0.000000 -0.000000 1.000000" />
      <limit effort="1" lower="-4.101523742186674" upper="4.101523742186674" velocity="6.28318530717959" />
      <dynamics damping="0" friction="0" />
    </joint>
    <transmission name="trans_6">
      <type>transmission_interface/SimpleTransmission</type>
      <joint name="joint_6">
	<hardwareInterface>PositionJointInterface</hardwareInterface>
      </joint>
      <actuator name="motor_6">
	<hardwareInterface>PositionJointInterface</hardwareInterface>
	<mechanicalReduction>1</mechanicalReduction>
      </actuator>
    </transmission>
  </xacro:macro>
</robot>
