<?xml version="1.0"?>
<!-- Copyright (C) 2021, TechMagic K.K. -->
<robot xmlns:xacro="http://www.ros.org/wiki/xacro">
  <xacro:property name="folder" value="package://denso_robot_descriptions/hm40a03w_description"/>
  <xacro:macro name="hm40a03w" params="parent *origin">
    <joint name="hm40a03w_base_joint" type="fixed">
      <xacro:insert_block name="origin"/>
      <parent link="${parent}"/>
      <child link="link_0"/>
    </joint>    
    <link name="link_0">
      <visual>
	<geometry>
	  <mesh filename="${folder}/mesh/hm40a03w_0.stl" scale="0.001 0.001 0.001"/>
	</geometry>
	<material name="white"/>
      </visual>
      <collision>
	<geometry>
	  <mesh filename="${folder}/mesh/hm40a03w_0.stl" scale="0.001 0.001 0.001"/>
	</geometry>
      </collision>
      <inertial>
	<mass value="1" />
	<inertia ixx="1" ixy="0" ixz="0" iyy="1" iyz="0" izz="1" />
      </inertial>
    </link>
    <joint name="joint_1" type="revolute">
      <parent link="link_0"/>
      <child link="link_1"/>
      <origin xyz="0 0 0.343" rpy="0 0 0"/>
      <axis xyz="0 0 1" />
      <limit effort="1" lower="${-pi}" upper="${pi}" velocity="1.0" />
      <dynamics damping="0" friction="0" />
    </joint>
    <link name="link_1">
      <visual>
	<geometry>
	  <mesh filename="${folder}/mesh/hm40a03w_1.stl" scale="0.001 0.001 0.001"/>
	</geometry>
	<material name="white"/>
      </visual>
      <collision>
	<geometry>
	  <mesh filename="${folder}/mesh/hm40a03w_1.stl" scale="0.001 0.001 0.001"/>
	</geometry>
      </collision>
      <inertial>
	<mass value="1" />
	<inertia ixx="1" ixy="0" ixz="0" iyy="1" iyz="0" izz="1" />
      </inertial>
    </link>
    <joint name="joint_2" type="revolute">
      <parent link="link_1" />
      <child link="link_2" />
      <origin xyz="0.5 0.0 0.105" rpy="0 0 0"/>
      <axis xyz="0 0 1" />
      <limit effort="1" lower="-${pi}" upper="${pi}" velocity="2.61799387799149" />
      <dynamics damping="0" friction="0" />
    </joint>
    <link name="link_2">
      <visual>
	<geometry>
	  <mesh filename="${folder}/mesh/hm40a03w_2.stl" scale="0.001 0.001 0.001"/>
	</geometry>
	<material name="white"/>
      </visual>
      <collision>
	<geometry>
	  <mesh filename="${folder}/mesh/hm40a03w_2.stl" scale="0.001 0.001 0.001"/>
	</geometry>
      </collision>
      <inertial>
	<mass value="1" />
	<inertia ixx="1" ixy="0" ixz="0" iyy="1" iyz="0" izz="1" />
      </inertial>
    </link>
    <joint name="joint_3" type="prismatic">
      <parent link="link_2" />
      <child link="link_3" />
      <origin xyz="0.5 0 ${-0.105-0.343}" />
      <axis xyz="0 0 1" />
      <limit effort="1" lower="0.01" upper="0.31" velocity="1.0" />
      <dynamics damping="0" friction="0" />
    </joint>
    <link name="link_3">
      <visual>
	<geometry>
	  <mesh filename="${folder}/mesh/hm40a03w_3.stl" scale="0.001 0.001 0.001"/>
	</geometry>
	<material name="white"/>
      </visual>
      <collision>
	<geometry>
	  <mesh filename="${folder}/mesh/hm40a03w_3.stl" scale="0.001 0.001 0.001"/>
	</geometry>
      </collision>
      <inertial>
	<mass value="1" />
	<inertia ixx="1" ixy="0" ixz="0" iyy="1" iyz="0" izz="1" />
      </inertial>
    </link>
    <joint name="joint_4" type="revolute">
      <parent link="link_3" />
      <child link="link_4" />
      <origin xyz="0 0 0" rpy="0 0 0"/>
      <axis xyz="0 0 1" />
      <limit effort="1" lower="-2.705260340591211" upper="2.705260340591211" velocity="3.92699081698724" />
      <dynamics damping="0" friction="0" />
    </joint>
    <link name="link_4">
    </link>
  </xacro:macro>
</robot>
